{"name": "测试数据：【 1532341，111111a，{except_result}，10000，token】", "status": "broken", "statusDetails": {"message": "TypeError: request() takes from 2 to 4 positional arguments but 5 were given", "trace": "self = <testcases.api_test.test_03_login.TestUserLogin object at 0x000001D97BC747B8>\nusername = '1532341', password = '111111a', login_type = 1, except_code = 10000\nexcept_msg = 'token'\nheaders = {'Content-Type': 'application/json', 'select_nation_id': 'RU'}\nurl = '/idserverhq/public/auth/login'\n\n    @allure.story(\"用例--登录用户\")\n    @allure.description(\"该用例是针对获取用户登录接口的测试\")\n    @allure.issue(\"https://www.cnblogs.com/wintest\", name=\"点击，跳转到对应BUG的链接地址\")\n    @allure.testcase(\"https://www.cnblogs.com/wintest\", name=\"点击，跳转到对应用例的链接地址\")\n    @allure.title(\"测试数据：【 {username}，{password}，{except_result}，{except_code}，{except_msg}】\")\n    @pytest.mark.single\n    @pytest.mark.parametrize(\"username, password, login_type, except_code, except_msg, headers, url\",\n                             api_data[\"test_login_user\"])\n    \n    def test_login_user(self, username, password, login_type, except_code, except_msg,headers,url):\n        logger.info(\"*************** 开始执行用例 ***************\")\n>       result = login_user(username, password, login_type,headers,url)\n\ntest_03_login.py:31: \n_ _ _ _ _ _ _ _ _ _ _ _ _ _ _ _ _ _ _ _ _ _ _ _ _ _ _ _ _ _ _ _ _ _ _ _ _ _ _ _\n..\\..\\operation\\user.py:103: in login_user\n    res = user.login(json=payload, headers=header, url=url)\n..\\..\\api\\user.py:27: in login\n    return self.post(**kwargs)\n_ _ _ _ _ _ _ _ _ _ _ _ _ _ _ _ _ _ _ _ _ _ _ _ _ _ _ _ _ _ _ _ _ _ _ _ _ _ _ _\n\nself = <api.user.User object at 0x000001D97B3D8320>\nurl = '/idserverhq/public/auth/login', data = None\njson = {'login_type': 1, 'password': '111111a', 'username': '1532341'}\nkwargs = {'headers': {'Content-Type': 'application/json', 'select_nation_id': 'RU'}}\n\n    def post(self,url=None,data=None, json=None, **kwargs):\n>       return self.request(url,\"POST\", data, json, **kwargs)\nE       TypeError: request() takes from 2 to 4 positional arguments but 5 were given\n\n..\\..\\core\\rest_client.py:31: TypeError"}, "description": "该用例是针对获取用户登录接口的测试", "attachments": [{"name": "log", "source": "0e6ee265-6127-49f1-983d-b3d760606ee7-attachment.txt", "type": "text/plain"}], "parameters": [{"name": "username", "value": "'1532341'"}, {"name": "password", "value": "'111111a'"}, {"name": "login_type", "value": "1"}, {"name": "except_code", "value": "10000"}, {"name": "except_msg", "value": "'token'"}, {"name": "headers", "value": "{'Content-Type': 'application/json', 'select_nation_id': 'RU'}"}, {"name": "url", "value": "'/idserverhq/public/auth/login'"}], "start": 1669426892149, "stop": 1669426892149, "uuid": "02cc52db-f08f-4b60-a0f4-04642b4c0804", "historyId": "0de4ecfae382e86437822b0a68f446dd", "testCaseId": "7272db244dabef390096479ae3196642", "fullName": "testcases.api_test.test_03_login.TestUserLogin#test_login_user", "labels": [{"name": "feature", "value": "用户登录模块"}, {"name": "epic", "value": "针对单个接口的测试"}, {"name": "severity", "value": "normal"}, {"name": "story", "value": "用例--登录用户"}, {"name": "tag", "value": "single"}, {"name": "parentSuite", "value": "testcases.api_test"}, {"name": "suite", "value": "test_03_login"}, {"name": "subSuite", "value": "TestUserLogin"}, {"name": "host", "value": "lijuan"}, {"name": "thread", "value": "19676-MainThread"}, {"name": "framework", "value": "pytest"}, {"name": "language", "value": "cpython3"}, {"name": "package", "value": "testcases.api_test.test_03_login"}], "links": [{"type": "test_case", "url": "https://www.cnblogs.com/wintest", "name": "点击，跳转到对应用例的链接地址"}, {"type": "issue", "url": "https://www.cnblogs.com/wintest", "name": "点击，跳转到对应BUG的链接地址"}]}